<?xml version="1.0" ?>
<!-- =================================================================================== -->
<!-- |    This document was autogenerated by xacro from ar_bot.xacro                   | -->
<!-- |    EDITING THIS FILE BY HAND IS NOT RECOMMENDED                                 | -->
<!-- =================================================================================== -->
<!--
Brennan Miller-Klugman

Purpose:
    URDF File for the AR Bot

Based off of:
    - the ROS URDF Tutorial: https://github.com/ros/urdf_tutorial/blob/master/urdf/06-flexible.urdf
    - URDF Tutorial by Articulated Robotics:
        https://github.com/joshnewans/articubot_one/blob/d5aa5e9bc9039073c0d8fd7fe426e170be79c087/description/robot_core.xacro
-->
<robot name="arbot">
  <material name="blue">
    <color rgba="0 0 0.8 1"/>
  </material>
  <material name="neon_blue">
    <color rgba="0 100 255 1"/>
  </material>
  <material name="black">
    <color rgba="0 0 0 1"/>
  </material>
  <link name="base_link">
    <visual>
      <origin rpy="0 0 0.03" xyz="0 0 0"/>
      <geometry>
        <box size="0.078 0.082 0.08"/>
      </geometry>
      <material name="blue"/>
    </visual>
    <collision>
      <geometry>
        <box size="0.078 0.082 0.08"/>
      </geometry>
    </collision>
    <inertial>
      <origin rpy="0 0 0.03" xyz="0 0 0"/>
      <mass value="0.05"/>
      <inertia ixx="5.468333333333333e-05" ixy="0" ixz="0" iyy="5.336666666666667e-05" iyz="0" izz="5.201666666666667e-05"/>
    </inertial>
  </link>
  <joint name="right_wheel_joint" type="continuous">
    <axis rpy="0 0 0" xyz="0 0 1"/>
    <parent link="base_link"/>
    <child link="right_wheel"/>
    <origin rpy="1.57075 0 0" xyz="0.015 -0.046 -0.02"/>
  </joint>
  <link name="right_wheel">
    <visual>
      <geometry>
        <cylinder length="0.008" radius="0.03"/>
      </geometry>
      <material name="black"/>
    </visual>
    <collision>
      <geometry>
        <cylinder length="0.008" radius="0.03"/>
      </geometry>
    </collision>
    <inertial>
      <origin rpy="0 0 0" xyz="0 0 0"/>
      <mass value="0.01"/>
      <inertia ixx="2.3033333333333326e-06" ixy="0.0" ixz="0.0" iyy="2.3033333333333326e-06" iyz="0.0" izz="4.5e-06"/>
    </inertial>
  </link>
  <joint name="left_wheel_joint" type="continuous">
    <axis rpy="0 0 0" xyz="0 0 1"/>
    <parent link="base_link"/>
    <child link="left_wheel"/>
    <origin rpy="1.57075 0 0" xyz="0.015 0.046 -0.02"/>
  </joint>
  <link name="left_wheel">
    <visual>
      <geometry>
        <cylinder length="0.008" radius="0.03"/>
      </geometry>
      <material name="black"/>
    </visual>
    <collision>
      <geometry>
        <cylinder length="0.008" radius="0.03"/>
      </geometry>
    </collision>
    <inertial>
      <origin rpy="0 0 0" xyz="0 0 0"/>
      <mass value="0.01"/>
      <inertia ixx="2.3033333333333326e-06" ixy="0.0" ixz="0.0" iyy="2.3033333333333326e-06" iyz="0.0" izz="4.5e-06"/>
    </inertial>
  </link>
  <joint name="caster_wheel_joint" type="fixed">
    <parent link="base_link"/>
    <child link="caster_wheel"/>
    <origin rpy="0 0 0" xyz="-0.027 0 -0.0475"/>
  </joint>
  <link name="caster_wheel">
    <visual>
      <geometry>
        <sphere radius="0.006"/>
      </geometry>
      <material name="black"/>
    </visual>
    <collision>
      <geometry>
        <sphere radius="0.006"/>
      </geometry>
    </collision>
    <inertial>
      <origin rpy="0 0 0" xyz="0 0 0"/>
      <mass value="0.01"/>
      <inertia ixx="1.4400000000000002e-07" ixy="0.0" ixz="0.0" iyy="1.4400000000000002e-07" iyz="0.0" izz="1.4400000000000002e-07"/>
    </inertial>
  </link>
</robot>